Workbook
Name _1001bqsllr6s: Feuil1!$A$29
Name _1fvuqjs6xfvv: Feuil1!$A$11
Name _1h997plu2r3q: Feuil1!#REF!
Name _1jsutjyckwia: Feuil1!$A$17
Name _1x11d5k5io24: Feuil1!#REF!
Name _25b71xk2i301: Feuil1!#REF!
Name _292kgykq0ye: Feuil1!$A$6
Name _2fo8i9cznxdf: Feuil1!$A$32
Name _2k99lr79hl9i: Feuil1!$A$5
Name _2utln1nfnqsx: Feuil1!$A$2
Name _3bxdsxq7p8gw: Feuil1!#REF!
Name _3f34v0rndqst: Feuil1!$A$31
Name _3ra657p5rfks: Feuil1!$A$4
Name _5ocrwot4q9or: Feuil1!#REF!
Name _62p8mewzupdh: Feuil1!$A$9
Name _63ehbuvcc3tw: Feuil1!#REF!
Name _6g3puvkrrskn: Feuil1!#REF!
Name _6onwknd2sl70: Feuil1!$A$7
Name _6sxpqe84lwy: Feuil1!#REF!
Name _6tacmrebr1p5: Feuil1!$A$3
Name _76u3b285zost: Feuil1!#REF!
Name _76x8livz92e3: Feuil1!#REF!
Name _7npq3rapq3b5: Feuil1!#REF!
Name _847vco2er5vx: Feuil1!#REF!
Name _8i1gdydhdqo8: Feuil1!#REF!
Name _8vd2wc5v9auo: Feuil1!#REF!
Name _92rzspumfy17: Feuil1!#REF!
Name _9cwk9m71vyqu: Feuil1!$A$34
Name _9hexdyk5v0wx: Feuil1!#REF!
Name _9jeesbxf4272: Feuil1!#REF!
Name _9o8iqnw0882k: Feuil1!#REF!
Name _9z5isgtp0zf3: Feuil1!$A$14
Name _a1blj5gc9j8j: Feuil1!#REF!
Name _a20iajxrewtn: Feuil1!#REF!
Name _a75ul79bzp21: Feuil1!#REF!
Name _atn6jtpgu1zu: Feuil1!$A$6
Name _b77wlvmmh9wq: Feuil1!#REF!
Name _be1fc6ea00hk: Feuil1!#REF!
Name _bp1acu9t2l5c: Feuil1!$A$16
Name _byzztlualq0q: Feuil1!#REF!
Name _ccy2pemctn8p: Feuil1!#REF!
Name _cgwcoegbkvui: Feuil1!$A$2
Name _chgzqrac0okr: Feuil1!#REF!
Name _dpycrk4r0ton: Feuil1!$A$30
Name _dsfs3jx2eyse: Feuil1!$A$15
Name _dwwrsfcgojso: Feuil1!#REF!
Name _e8p5frs5ytai: Feuil1!$A$3
Name _eltq1ml39i8g: Feuil1!#REF!
Name _f4und4vdlss2: Feuil1!#REF!
Name _g0y5qe76r34g: Feuil1!#REF!
Name _g70xgby2qf4: Feuil1!$A$4
Name _g8ek9utgccwp: Feuil1!#REF!
Name _g9qmie434sne: Feuil1!#REF!
Name _gawbf46ma6oj: Feuil1!#REF!
Name _gelkcw7y8ynz: Feuil1!#REF!
Name _gfdhz1jncvev: Feuil1!$A$20
Name _h0mvoz49fm6v: Feuil1!$A$12
Name _hdt4xnw2zsex: Feuil1!#REF!
Name _hm9eh7d297ex: Feuil1!#REF!
Name _hmf5bodeq1eo: Feuil1!#REF!

Sheet Definitions
A1: mot | B1: definition
A2: A.F.F.F. | B2: Agents Formant un Film Flottant
A3: A.E.S. | B3: Alimentation Électrique de Sécurité
A4: A.G.S. | B4: Alarme Générale Sélective
A5: A.P.S. | B5: Alimentation Pneumatique de Sécurité
A6: A.U. | B6: Arrêt d'Urgence
A7: B.A.A.S. | B7: Bloc Autonome d'Alarme Sonore
A8: B.A.A.S. Ma | B8: Bloc Autonome d'Alarme Sonore Manuel
A9: B.A.A.S. Pr | B9: Bloc Autonome d'Alarme Sonore Principal
A10: B.A.A.S. Sa | B10: Bloc Autonome d'Alarme Sonore Satellite
A11: B.A.E.S. | B11: Bloc Autonome d'Éclairage de Sécurité
A12: B.A.P.I. | B12: Bloc Autonome Portable d'Intervention
... A94: Z.S. | B94: Zone de Mise en Sécurité

Sheet Liste_Questions
A1: UV | B1: Numéro Question | C1: Intitulé de la Question | D1: Proposition A | E1: Proposition B | F1: Proposition C | G1: Proposition D | H1: Proposition E | I1: Proposition F | J1: Proposition G | K1: BonneRéponse | L1: Comentaire
A2: UV01 (1) | B2: 1 | C2: Quels combustibles forment des braises au cours de leur combustion ? | D2: Les liquides | E2: Les solides | F2: Les gaz | G2: Les fumées | H2: Aucune des réponses précédentes | K2: B
A3: UV01 (1) | B3: 2 | C3: Quels sont les éléments qui constituent le triangle du feu ? | D3: Le gaz carbonique | E3: Le comburant | F3: Le combustible | G3: L’énergie d’activation | H3: La poudre | I3: L’eau avec additif | J3: Aucune des réponses précédentes | K3: B,C,D
A4: UV01 (1) | B4: 3 | C4: Parmi ces propositions indiquez le (ou les) comburant(s) ? | D4: Un combustible liquide appelé aussi carburant | E4: Le gaz carbonique | F4: La chaleur | G4: L’oxygène de l’air | H4: La couche d’ozone | I4: Aucune des réponses précédentes | K4: D
A5: UV01 (1) | B5: 4 | C5: Parmi ces propositions, indiquez celle(s) considérée(s) comme étant un comburant ? | D5: Le propane | E5: Les flammes | F5: L’huile hydraulique | G5: L’oxygène | H5: L’essence | I5: Aucune des réponses précédentes | K5: D
A6: UV01 (1) | B6: 5 | C6: La combustion est une réaction : | D6: Exothermocimétrique | E6: Exothermique | F6: Oxydable | G6: Exothérique | H6: Extra-thermique | I6: Aucune des réponses précédentes | K6: B
A7: UV01 (1) | B7: 6 | C7: Quelles sont les différentes causes des incendies ? | D7: Naturelles | E7: Catastrophiques | F7: Humaines | G7: Techniques | H7: Réelles | I7: Aucune des réponses précédentes | K7: A,C,D
A8: UV01 (1) | B8: 7 | C8: Un incendie peut être d’origine : | D8: Alimentaire | E8: Humaine | F8: Naturelle | G8: Électrique | H8: Hydraulique | I8: Aucune des réponses précédentes | K8: B,C,D
A9: UV01 (1) | B9: 8 | C9: Afin de déterminer les agents extincteurs à utiliser, comment classe-t-on les familles de combustibles ? | D9: En fonction de leur dangerosité | E9: En fonction du type de combustion (lente, vive, spontanée) | F9: En fonction de leurs points éclair | G9: En fonction de leurs états (solide, liquide, gaz) | H9: Aucune des réponses précédentes | K9: D
A10: UV01 (1) | B10: 9 | C10: Quels sont, parmi les propositions suivantes, les éléments qui appartiennent à la classe de feu D ? | D10: Le bois | E10: L’aluminium | F10: Le butane | G10: Le sodium | H10: Aucune des réponses précédentes | K10: B,D
A11: UV01 (1) | B11: 10 | C11: Quels sont, parmi les propositions suivantes, les éléments qui appartiennent à la classe de feu B ? | D11: L’huile moteur | E11: L’alcool | F11: La paille | G11: Certains plastiques | H11: L’oxygène | I11: Aucune des réponses précédentes | K11: A,B,D
A12: UV01 (1) | B12: 11 | C12: Qu’est-ce que la convection dans un feu ? | D12: C’est la transmission de la chaleur par la masse même du matériau | E12: C’est la transmission de la chaleur par l’intermédiaire de l’air | F12: C’est la transmission de la chaleur par l’intermédiaire d’ondes électromagnétiques | G12: C’est la transmission de la chaleur par l’intermédiaire de particules incandescentes | H12: Aucune des réponses précédentes | K12: B
A13: UV01 (1) | B13: 12 | C13: Comment se propage la chaleur par rayonnement ? | D13: Par la masse du matériau | E13: Par projection de particules incandescentes | F13: Par déplacement de la fumée | G13: Par mouvement des gaz chauds | H13: Par l’intermédiaire d’ondes électromagnétiques | I13: Aucune des réponses précédentes | K13: E
A14: UV01 (1) | B14: 13 | C14: Qu’est-ce que la conduction dans un feu ? | D14: C’est la transmission de la chaleur par la masse même du matériau | E14: C’est la transmission de la chaleur par l’intermédiaire de l’air | F14: C’est la transmission de la chaleur par l’intermédiaire d’ondes électromagnétiques | G14: C’est la transmission de la chaleur par l’intermédiaire de particules incandescentes | H14: Aucune des réponses précédentes | K14: A
A15: UV01 (1) | B15: 14 | C15: Quels sont les modes de propagation d’un incendie ? | D15: Le rayonnement | E15: Les projections | F15: La conviction | G15: La conduction | H15: La fragmentation | I15: La convection | J15: Aucune des réponses précédentes | K15: A,B,D,F
A16: UV01 (2) | B16: 1 | C16: À quoi s’applique la résistance au feu ? | D16: Aux matériaux utilisés pour l’ameublement | E16: Aux éléments de construction | F16: Aux revêtements de sol | G16: Aux piliers | H16: À la quantité de chaleur dégagée | I16: Aucune des réponses précédentes | K16: B,D | L16: La résistance au feu concerne la capacité des éléments de construction à conserver leurs fonctions (portance, étanchéité, isolation) pendant un temps donné en cas d’incendie. Elle ne s’applique pas aux meubles ou objets.
A17: UV01 (2) | B17: 2 | C17: Comment sont exprimées les durées de résistance au feu, dans les euroclasses ? | D17: En secondes | E17: En minutes | F17: En heures | G17: En heures et minutes | H17: Aucune des réponses précédentes | K17: B | L17: Les euroclasses utilisent les critères R, E, I suivis d’un nombre en minutes (ex. REI 120 = coupe-feu pendant 120 minutes).
A18: UV01 (2) | B18: 3 | C18: SF-PF-CF correspondent : | D18: À la résistance au feu des éléments de construction | E18: À la réaction au feu des matériaux de construction | F18: Aux niveaux d’accès du S.S.I | G18: Aux classements d’E.R.P | H18: Aucune des réponses précédentes | K18: A | L18: SF = Stable au feu (résistance mécanique) PF = Pare-flammes (étanchéité aux flammes) CF = Coupe-feu (étanchéité + isolation thermique)
A19: UV01 (2) | B19: 4 | C19: La réaction au feu d’un matériau peut être notée : | D19: SF | E19: A1 | F19: CF | G19: M0 | H19: M2 | I19: Aucune des réponses précédentes | K19: B,D,E | L19: A1 = Euroclasse (incombustible) M0, M1, M2, M3, M4 = Classement français (réaction au feu) SF et CF concernent la résistance au feu, pas la réaction.
A20: UV01 (2) | B20: 5 | C20: Le classement M1 correspond à : | D20: La résistance au feu d’une porte | E20: Le potentiel d’extinction d’un extincteur | F20: La réaction au feu d’un matériau | G20: La manœuvre mensuelle obligatoire | H20: Aucune des réponses précédentes | K20: C | L20: M1 = matériau combustible mais non inflammable (ex. PVC rigide, composites).
A21: UV01 (2) | B21: 6 | C21: Un classement de réaction au feu est demandé pour : | D21: Un revêtement mural | E21: Un rétroprojecteur | F21: Un revêtement de sol | G21: Un gros mobilier | H21: Aucune des réponses précédentes | K21: A,C,D | L21: Les revêtements (murs, sols, plafonds) doivent respecter des exigences de réaction au feu (M1, M2, M3 selon zones). Le gros mobilier est défini comme étant le mobilier constituant l'agencement principal. Il comprend ainsi les comptoirs d'accueil, bars, rayonnages, cloisonnements… Pour les ERP des catégories 1 à 4, le gros mobilier doit être en matériau de catégorie M3 (moyennement inflammable)
A22: UV01 (2) | B22: 7 | C22: En ERP, donnez les principales règles pour le revêtement des escaliers encloisonnés ? | D22: M1 pour les murs | E22: M2 pour le sol | F22: M3 pour le plafond | G22: M4 pour le sol | H22: M1 pour le plafond | I22: M3 pour le sol | J22: Aucune des réponses précédentes | K22: A,E,F | L22: C’est la règle du 311 : murs et plafonds M1, sols M3.
A23: UV01 (2) | B23: 8 | C23: La résistance au feu s’applique : | D23: Aux meubles | E23: Aux sapins de Noël | F23: Aux objets | G23: Aux éléments de construction | H23: Aucune des réponses précédentes | K23: D | L23: Elle concerne les structures (poteaux, murs, planchers, portes), pas les meubles ou objets.
A24: UV01 (2) | B24: 9 | C24: Un élément de construction qui résiste au feu peut être classé : | D24: Coupe-feu | E24: REI | F24: Pare-feu | G24: A.E.S. | H24: Stable au feu | I24: Aucune des réponses précédentes | K24: A,B,C,E | L24: SF, PF, CF = ancien système français REI = système européen (R = portance, E = étanchéité, I = isolation)
A25: UV02 | B25: 1 | C25: Quel établissement suivant est classé en type OA ? | D25: Un hôtel habité | E25: Un hôtel d’altitude | F25: Une habitation occupée | G25: Un organisme agréé | H25: Aucune des réponses précédentes | K25: B
A26: UV02 | B26: 2 | C26: Qu’est-ce qu’un établissement de type PA ? | D26: Un parc automobile | E26: Un stand de tir | F26: Un centre de formation professionnel pour adultes | G26: Aucune des réponses précédentes | K26: D
A27: UV02 | B27: 3 | C27: Parmi les établissements suivants, lesquels sont des ERP ? | D27: Un train de voyageur | E27: Un parc d’exposition | F27: Une salle de concert | G27: Un dépôt de gaz | H27: Une menuiserie | I27: Aucune des réponses précédentes | K27: B,C
A28: UV02 | B28: 4 | C28: Quel règlement de sécurité incendie est applicable aux E.R.P. du 1er groupe ? | D28: L’arrêté du 08 mai 1968 modifié | E28: L’arrêté du 18 octobre 1977 modifié | F28: L’arrêté du 25 juin 1980 modifié | G28: L’arrêté du 02 mai 2005 modifié | H28: L’arrêté du 23 août 2008 modifié | I28: Aucune des réponses précédentes | K28: C
A29: UV02 | B29: 5 | C29: Une maison d’accueil pour handicapés pouvant recevoir 308 personnes est classée : | D29: Type J | E29: Type U | F29: Type R | G29: 2ème catégorie | H29: 3ème catégorie | I29: 4ème catégorie | J29: Aucune des réponses précédentes | K29: A,E
A30: UV02 | B30: 6 | C30: Les ERP sont classés par catégorie en fonction : | D30: Du nombre maximum de personnes admises | E30: Du nombre d’étages | F30: Du nombre de locaux | G30: Du nombre de sorties | H30: Aucune des réponses précédentes | K30: A
A31: UV03 | B31: 1 | C31: Les IGH à usage exclusif de bureaux sont classés de la façon suivante : | D31: GHZ | E31: GHR | F31: GHW1 | G31: GHW2 | H31: Aucune des réponses précédentes | K31: C,D
A32: UV03 | B32: 2 | C32: Le classement d’un bâtiment en immeuble de grande hauteur est déterminé d’après : | D32: La catégorie de l’établissement | E32: La surface accessible au public | F32: La hauteur du plancher bas du dernier niveau | G32: La commission de sécurité compétente | H32: Aucune des réponses précédentes | K32: C
A33: UV03 | B33: 3 | C33: Qu’est-ce qu’un GH S ? | D33: Un IGH à usage mixte | E33: Un IGH d’enseignement | F33: Un IGH d’habitation | G33: Un IGH d’archives | H33: Aucune des réponses précédentes | K33: D
A34: UV03 | B34: 4 | C34: Est considéré comme IGH, tout bâtiment dont le plancher bas du dernier niveau est situé à plus de : | D34: 50 mètres pour les immeubles à usage d’habitation | E34: 28 mètres pour les immeubles ne relevant pas de l’habitation | F34: 28 mètres pour les immeubles à usage d’habitation | G34: Aucune des réponses précédentes | K34: A,B
A35: UV03 | B35: 5 | C35: Un immeuble à usage de bureau dont le plancher bas du dernier niveau est situé à 18 mètres de hauteur sera classé en : | D35: GH U | E35: GH W1 | F35: GH W2 | G35: GH Z | H35: Aucune des réponses précédentes | K35: E
A36: UV03 | B36: 6 | C36: Qu’est-ce qu’un GH U ? | D36: Un IGH à usage d’habitation | E36: Un IGH à usage de bureaux | F36: Un IGH à usage mixte | G36: Un IGH à usage d’archives | H36: Aucune des réponses précédentes | K36: E
A37: UV03 | B37: 7 | C37: Qu’est-ce qu’un GH A ? | D37: Un IGH d’habitation | E37: Un IGH de bureaux | F37: Un IGH hôtelier | G37: Un IGH hospitalier | H37: Aucune des réponses précédentes | K37: A
A38: UV04 (1) | B38: 1 | C38: Quels sont les principes généraux de sécurité en ERP ? | D38: Assurer uniquement la sauvegarde des biens | E38: Permettre une évacuation rapide et sûre des occupants | F38: Gérer le sinistre à la place des secours extérieurs | G38: Limiter la propagation du feu | H38: Faciliter l’intervention des secours | I38: Aucune des réponses précédentes | K38: B,D,E
A39: UV04 (1) | B39: 2 | C39: En règle générale, un ERP est considéré comme isolé s’il est situé à une distance minimum de : | D39: 1 mètre du tiers | E39: 2 mètres du tiers | F39: 3 mètres du tiers | G39: 8 mètres du tiers | H39: Aucune des réponses précédentes | K39: D
A40: UV04 (1) | B40: 3 | C40: Quelle est l’utilité des baies accessibles ? | D40: Elles permettent l’intervention des équipes de sécurité | E40: Elles permettent l’intervention des services de secours | F40: Elles permettent l’évacuation normale du public | G40: Elles facilitent le nettoyage | H40: Elles permettent la ventilation | I40: Aucune des réponses précédentes | K40: B
...

Sheet Liste_UV
A1: UV | B1: Titre | C1: Description | D1: Nb_Questions
A2: UV01 (1) | B2: Le Feu | C2: =B2 & " (" & D2 & " questions)" -> Le Feu (14 questions) | D2: =COUNTIF(Liste_Questions!$A:$A,$A2) -> 14 | E2: =COUNTIF(Liste_Questions!$C:$C,"["&LEFT($A2,4)&"]*") -> 0
A3: UV01 (2) | B3: Le Feu | C3: =B3 & " (" & D3 & " questions)" -> Le Feu (9 questions) | D3: =COUNTIF(Liste_Questions!$A:$A,$A3) -> 9 | E3: =COUNTIF(Liste_Questions!$C:$C,"["&LEFT($A3,4)&"]*") -> 0
A4: UV02 | B4: Classement des ERP | C4: =B4 & " (" & D4 & " questions)" -> Classement des ERP (6 questions) | D4: =COUNTIF(Liste_Questions!$A:$A,$A4) -> 6 | E4: =COUNTIF(Liste_Questions!$C:$C,"["&LEFT($A4,4)&"]*") -> 0
A5: UV03 | B5: Classement des IGH | C5: =B5 & " (" & D5 & " questions)" -> Classement des IGH (7 questions) | D5: =COUNTIF(Liste_Questions!$A:$A,$A5) -> 7 | E5: =COUNTIF(Liste_Questions!$C:$C,"["&LEFT($A5,4)&"]*") -> 0
A6: UV04 (1) | B6: Sécurité incendie en ERP | C6: =B6 & " (" & D6 & " questions)" -> Sécurité incendie en ERP (14 questions) | D6: =COUNTIF(Liste_Questions!$A:$A,$A6) -> 14 | E6: =COUNTIF(Liste_Questions!$C:$C,"["&LEFT($A6,4)&"]*") -> 0
A7: UV04 (2) | B7: Sécurité incendie en ERP | C7: =B7 & " (" & D7 & " questions)" -> Sécurité incendie en ERP (12 questions) | D7: =COUNTIF(Liste_Questions!$A:$A,$A7) -> 12 | E7: =COUNTIF(Liste_Questions!$C:$C,"["&LEFT($A7,4)&"]*") -> 0
A8: UV05 | B8: Sécurité incendie en IGH | C8: =B8 & " (" & D8 & " questions)" -> Sécurité incendie en IGH (16 questions) | D8: =COUNTIF(Liste_Questions!$A:$A,$A8) -> 16 | E8: =COUNTIF(Liste_Questions!$C:$C,"["&LEFT($A8,4)&"]*") -> 0
A9: UV06 | B9: Les moyens de secours | C9: =B9 & " (" & D9 & " questions)" -> Les moyens de secours (13 questions) | D9: =COUNTIF(Liste_Questions!$A:$A,$A9) -> 13 | E9: =COUNTIF(Liste_Questions!$C:$C,"["&LEFT($A9,4)&"]*") -> 0
A10: UV07 | B10: Les installations électriques | C10: =B10 & " (" & D10 & " questions)" -> Les installations électriques (16 questions) | D10: =COUNTIF(Liste_Questions!$A:$A,$A10) -> 16 | E10: =COUNTIF(Liste_Questions!$C:$C,"["&LEFT($A10,4)&"]*") -> 0
A11: UV08 | B11: Le S.S.I. | C11: =B11 & " (" & D11 & " questions)" -> Le S.S.I. (20 questions) | D11: =COUNTIF(Liste_Questions!$A:$A,$A11) -> 20 | E11: =COUNTIF(Liste_Questions!$C:$C,"["&LEFT($A11,4)&"]*") -> 0
A12: UV09 (1) | B12: Rôles et missions des agents | C12: =B12 & " (" & D12 & " questions)" -> Rôles et missions des agents (0 questions) | D12: =COUNTIF(Liste_Questions!$A:$A,$A12) -> 0 | E12: =COUNTIF(Liste_Questions!$C:$C,"["&LEFT($A12,4)&"]*") -> 0
A13: UV09 (2) | C13: =B13 & " (" & D13 & " questions)" -> (0 questions) | D13: =COUNTIF(Liste_Questions!$A:$A,$A13) -> 0 | E13: =COUNTIF(Liste_Questions!$C:$C,"["&LEFT($A13,4)&"]*") -> 0
A14: VRAC (1) | C14: UV en vrac (20 questions) | D14: =COUNTIF(Liste_Questions!$A:$A,$A14) -> 0
A15: VRAC (2) | C15: UV en vrac (20 questions) | D15: =COUNTIF(Liste_Questions!$A:$A,$A15) -> 0

Sheet Feuil1
A1: [1] Le feu (4) | B1: =FIND(". ",A1) -> #VALUE! | C1: =RIGHT(A1, LEN(A1)-(B1+1)) -> #VALUE! | D1: {=_xlfn.TEXTSPLIT(C1,"|")} -> #VALUE!
A2: [1.1] Le feu partie 1 | B2: =FIND(". ",A2) -> #VALUE! | C2: =RIGHT(A2, LEN(A2)-(B2+1)) -> #VALUE! | D2: {=_xlfn.TEXTSPLIT(C2,"|")} -> #VALUE!
A3: 1. Quels combustibles forment des braises au cours de leur combustion ?|Les liquides|Les solides|Les gaz|Les fumées|Aucune des réponses précédentes | B3: =FIND(". ",A3) -> 2 | C3: =RIGHT(A3, LEN(A3)-(B3+1)) -> Quels combustibles forment des braises au cours de leur combustion ?|Les liquides|Les solides|Les gaz|Les fumées|Aucune des réponses précédentes | D3: {=_xlfn.TEXTSPLIT(C3,"|")} -> Quels combustibles forment des braises au cours de leur combustion ? | E3: Les liquides | F3: Les solides | G3: Les gaz | H3: Les fumées | I3: Aucune des réponses précédentes
A4: 2. Quels sont les éléments qui constituent le triangle du feu ?|Le gaz carbonique|Le comburant|Le combustible|L’énergie d’activation|La poudre|L’eau avec additif|Aucune des réponses précédentes | B4: =FIND(". ",A4) -> 2 | C4: =RIGHT(A4, LEN(A4)-(B4+1)) -> Quels sont les éléments qui constituent le triangle du feu ?|Le gaz carbonique|Le comburant|Le combustible|L’énergie d’activation|La poudre|L’eau avec additif|Aucune des réponses précédentes | D4: {=_xlfn.TEXTSPLIT(C4,"|")} -> Quels sont les éléments qui constituent le triangle du feu ? | E4: Le gaz carbonique | F4: Le comburant | G4: Le combustible | H4: L’énergie d’activation | I4: La poudre | J4: L’eau avec additif | K4: Aucune des réponses précédentes
A5: 3. Parmi ces propositions indiquez le (ou les) comburant(s) ?|Un combustible liquide appelé aussi carburant|Le gaz carbonique|La chaleur|L’oxygène de l’air|La couche d’ozone|Aucune des réponses précédentes | B5: =FIND(". ",A5) -> 2 | C5: =RIGHT(A5, LEN(A5)-(B5+1)) -> Parmi ces propositions indiquez le (ou les) comburant(s) ?|Un combustible liquide appelé aussi carburant|Le gaz carbonique|La chaleur|L’oxygène de l’air|La couche d’ozone|Aucune des réponses précédentes | D5: {=_xlfn.TEXTSPLIT(C5,"|")} -> Parmi ces propositions indiquez le (ou les) comburant(s) ? | E5: Un combustible liquide appelé aussi carburant | F5: Le gaz carbonique | G5: La chaleur | H5: L’oxygène de l’air | I5: La couche d’ozone | J5: Aucune des réponses précédentes
A6: 4. Parmi ces propositions, indiquez celle(s) considérée(s) comme étant un comburant ?|Le propane|Les flammes|L’huile hydraulique|L’oxygène|L’essence|Aucune des réponses précédentes | B6: =FIND(". ",A6) -> 2 | C6: =RIGHT(A6, LEN(A6)-(B6+1)) -> Parmi ces propositions, indiquez celle(s) considérée(s) comme étant un comburant ?|Le propane|Les flammes|L’huile hydraulique|L’oxygène|L’essence|Aucune des réponses précédentes | D6: {=_xlfn.TEXTSPLIT(C6,"|")} -> Parmi ces propositions, indiquez celle(s) considérée(s) comme étant un comburant ? | E6: Le propane | F6: Les flammes | G6: L’huile hydraulique | H6: L’oxygène | I6: L’essence | J6: Aucune des réponses précédentes
A7: 5. La combustion est une réaction :|Exothermocimétrique|Exothermique|Oxydable|Exothérique|Extra-thermique|Aucune des réponses précédentes | B7: =FIND(". ",A7) -> 2 | C7: =RIGHT(A7, LEN(A7)-(B7+1)) -> La combustion est une réaction :|Exothermocimétrique|Exothermique|Oxydable|Exothérique|Extra-thermique|Aucune des réponses précédentes | D7: {=_xlfn.TEXTSPLIT(C7,"|")} -> La combustion est une réaction : | E7: Exothermocimétrique | F7: Exothermique | G7: Oxydable | H7: Exothérique | I7: Extra-thermique | J7: Aucune des réponses précédentes
A8: 6. Quelles sont les différentes causes des incendies ?|Naturelles|Catastrophiques|Humaines|Techniques|Réelles|Aucune des réponses précédentes | B8: =FIND(". ",A8) -> 2 | C8: =RIGHT(A8, LEN(A8)-(B8+1)) -> Quelles sont les différentes causes des incendies ?|Naturelles|Catastrophiques|Humaines|Techniques|Réelles|Aucune des réponses précédentes | D8: {=_xlfn.TEXTSPLIT(C8,"|")} -> Quelles sont les différentes causes des incendies ? | E8: Naturelles | F8: Catastrophiques | G8: Humaines | H8: Techniques | I8: Réelles | J8: Aucune des réponses précédentes
A9: 7. Un incendie peut être d’origine :|Alimentaire|Humaine|Naturelle|Électrique|Hydraulique|Aucune des réponses précédentes | B9: =FIND(". ",A9) -> 2 | C9: =RIGHT(A9, LEN(A9)-(B9+1)) -> Un incendie peut être d’origine :|Alimentaire|Humaine|Naturelle|Électrique|Hydraulique|Aucune des réponses précédentes | D9: {=_xlfn.TEXTSPLIT(C9,"|")} -> Un incendie peut être d’origine : | E9: Alimentaire | F9: Humaine | G9: Naturelle | H9: Électrique | I9: Hydraulique | J9: Aucune des réponses précédentes
A10: 8. Afin de déterminer les agents extincteurs à utiliser, comment classe-t-on les familles de combustibles ?|En fonction de leur dangerosité|En fonction du type de combustion (lente, vive, spontanée)|En fonction de leurs points éclair|En fonction de leurs états (solide, liquide, gaz)|Aucune des réponses précédentes | B10: =FIND(". ",A10) -> 2 | C10: =RIGHT(A10, LEN(A10)-(B10+1)) -> Afin de déterminer les agents extincteurs à utiliser, comment classe-t-on les familles de combustibles ?|En fonction de leur dangerosité|En fonction du type de combustion (lente, vive, spontanée)|En fonction de leurs points éclair|En fonction de leurs états (solide, liquide, gaz)|Aucune des réponses précédentes | D10: {=_xlfn.TEXTSPLIT(C10,"|")} -> Afin de déterminer les agents extincteurs à utiliser, comment classe-t-on les familles de combustibles ? | E10: En fonction de leur dangerosité | F10: En fonction du type de combustion (lente, vive, spontanée) | G10: En fonction de leurs points éclair | H10: En fonction de leurs états (solide, liquide, gaz) | I10: Aucune des réponses précédentes
A11: 9. Quels sont, parmi les propositions suivantes, les éléments qui appartiennent à la classe de feu D ?|Le bois|L’aluminium|Le butane|Le sodium|Aucune des réponses précédentes | B11: =FIND(". ",A11) -> 2 | C11: =RIGHT(A11, LEN(A11)-(B11+1)) -> Quels sont, parmi les propositions suivantes, les éléments qui appartiennent à la classe de feu D ?|Le bois|L’aluminium|Le butane|Le sodium|Aucune des réponses précédentes | D11: {=_xlfn.TEXTSPLIT(C11,"|")} -> Quels sont, parmi les propositions suivantes, les éléments qui appartiennent à la classe de feu D ? | E11: Le bois | F11: L’aluminium | G11: Le butane | H11: Le sodium | I11: Aucune des réponses précédentes
A12: 10. Quels sont, parmi les propositions suivantes, les éléments qui appartiennent à la classe de feu B ?|L’huile moteur|L’alcool|La paille|Certains plastiques|L’oxygène|Aucune des réponses précédentes | B12: =FIND(". ",A12) -> 3 | C12: =RIGHT(A12, LEN(A12)-(B12+1)) -> Quels sont, parmi les propositions suivantes, les éléments qui appartiennent à la classe de feu B ?|L’huile moteur|L’alcool|La paille|Certains plastiques|L’oxygène|Aucune des réponses précédentes | D12: {=_xlfn.TEXTSPLIT(C12,"|")} -> Quels sont, parmi les propositions suivantes, les éléments qui appartiennent à la classe de feu B ? | E12: L’huile moteur | F12: L’alcool | G12: La paille | H12: Certains plastiques | I12: L’oxygène | J12: Aucune des réponses précédentes
A13: 11. Qu’est-ce que la convection dans un feu ?|C’est la transmission de la chaleur par la masse même du matériau|C’est la transmission de la chaleur par l’intermédiaire de l’air|C’est la transmission de la chaleur par l’intermédiaire d’ondes électromagnétiques|C’est la transmission de la chaleur par l’intermédiaire de particules incandescentes|Aucune des réponses précédentes | B13: =FIND(". ",A13) -> 3 | C13: =RIGHT(A13, LEN(A13)-(B13+1)) -> Qu’est-ce que la convection dans un feu ?|C’est la transmission de la chaleur par la masse même du matériau|C’est la transmission de la chaleur par l’intermédiaire de l’air|C’est la transmission de la chaleur par l’intermédiaire d’ondes électromagnétiques|C’est la transmission de la chaleur par l’intermédiaire de particules incandescentes|Aucune des réponses précédentes | D13: {=_xlfn.TEXTSPLIT(C13,"|")} -> Qu’est-ce que la convection dans un feu ? | E13: C’est la transmission de la chaleur par la masse même du matériau | F13: C’est la transmission de la chaleur par l’intermédiaire de l’air | G13: C’est la transmission de la chaleur par l’intermédiaire d’ondes électromagnétiques | H13: C’est la transmission de la chaleur par l’intermédiaire de particules incandescentes | I13: Aucune des réponses précédentes
A14: 12. Comment se propage la chaleur par rayonnement ?|Par la masse du matériau|Par projection de particules incandescentes|Par déplacement de la fumée|Par mouvement des gaz chauds|Par l’intermédiaire d’ondes électromagnétiques|Aucune des réponses précédentes | B14: =FIND(". ",A14) -> 3 | C14: =RIGHT(A14, LEN(A14)-(B14+1)) -> Comment se propage la chaleur par rayonnement ?|Par la masse du matériau|Par projection de particules incandescentes|Par déplacement de la fumée|Par mouvement des gaz chauds|Par l’intermédiaire d’ondes électromagnétiques|Aucune des réponses précédentes | D14: {=_xlfn.TEXTSPLIT(C14,"|")} -> Comment se propage la chaleur par rayonnement ? | E14: Par la masse du matériau | F14: Par projection de particules incandescentes | G14: Par déplacement de la fumée | H14: Par mouvement des gaz chauds | I14: Par l’intermédiaire d’ondes électromagnétiques | J14: Aucune des réponses précédentes
A15: 13. Qu’est-ce que la conduction dans un feu ?|C’est la transmission de la chaleur par la masse même du matériau|C’est la transmission de la chaleur par l’intermédiaire de l’air|C’est la transmission de la chaleur par l’intermédiaire d’ondes électromagnétiques|C’est la transmission de la chaleur par l’intermédiaire de particules incandescentes|Aucune des réponses précédentes | B15: =FIND(". ",A15) -> 3 | C15: =RIGHT(A15, LEN(A15)-(B15+1)) -> Qu’est-ce que la conduction dans un feu ?|C’est la transmission de la chaleur par la masse même du matériau|C’est la transmission de la chaleur par l’intermédiaire de l’air|C’est la transmission de la chaleur par l’intermédiaire d’ondes électromagnétiques|C’est la transmission de la chaleur par l’intermédiaire de particules incandescentes|Aucune des réponses précédentes | D15: {=_xlfn.TEXTSPLIT(C15,"|")} -> Qu’est-ce que la conduction dans un feu ? | E15: C’est la transmission de la chaleur par la masse même du matériau | F15: C’est la transmission de la chaleur par l’intermédiaire de l’air | G15: C’est la transmission de la chaleur par l’intermédiaire d’ondes électromagnétiques | H15: C’est la transmission de la chaleur par l’intermédiaire de particules incandescentes | I15: Aucune des réponses précédentes
A16: 14. Quels sont les modes de propagation d’un incendie ?|Le rayonnement|Les projections|La conviction|La conduction|La fragmentation|La convection|Aucune des réponses précédentes | B16: =FIND(". ",A16) -> 3 | C16: =RIGHT(A16, LEN(A16)-(B16+1)) -> Quels sont les modes de propagation d’un incendie ?|Le rayonnement|Les projections|La conviction|La conduction|La fragmentation|La convection|Aucune des réponses précédentes | D16: {=_xlfn.TEXTSPLIT(C16,"|")} -> Quels sont les modes de propagation d’un incendie ? | E16: Le rayonnement | F16: Les projections | G16: La conviction | H16: La conduction | I16: La fragmentation | J16: La convection | K16: Aucune des réponses précédentes
A17: [1.2] Le feu partie 2 | B17: =FIND(". ",A17) -> #VALUE! | C17: =RIGHT(A17, LEN(A17)-(B17+1)) -> #VALUE! | D17: {=_xlfn.TEXTSPLIT(C17,"|")} -> #VALUE!
A18: 1. À quoi s’applique la résistance au feu ?|Aux matériaux utilisés pour l’ameublement|Aux éléments de construction|Aux revêtements de sol|Aux piliers|À la quantité de chaleur dégagée|Aucune des réponses précédentes | B18: =FIND(". ",A18) -> 2 | C18: =RIGHT(A18, LEN(A18)-(B18+1)) -> À quoi s’applique la résistance au feu ?|Aux matériaux utilisés pour l’ameublement|Aux éléments de construction|Aux revêtements de sol|Aux piliers|À la quantité de chaleur dégagée|Aucune des réponses précédentes | D18: {=_xlfn.TEXTSPLIT(C18,"|")} -> À quoi s’applique la résistance au feu ? | E18: Aux matériaux utilisés pour l’ameublement | F18: Aux éléments de construction | G18: Aux revêtements de sol | H18: Aux piliers | I18: À la quantité de chaleur dégagée | J18: Aucune des réponses précédentes
A19: 2. Comment sont exprimées les durées de résistance au feu, dans les euroclasses ?|En secondes|En minutes|En heures|En heures et minutes|Aucune des réponses précédentes | B19: =FIND(". ",A19) -> 2 | C19: =RIGHT(A19, LEN(A19)-(B19+1)) -> Comment sont exprimées les durées de résistance au feu, dans les euroclasses ?|En secondes|En minutes|En heures|En heures et minutes|Aucune des réponses précédentes | D19: {=_xlfn.TEXTSPLIT(C19,"|")} -> Comment sont exprimées les durées de résistance au feu, dans les euroclasses ? | E19: En secondes | F19: En minutes | G19: En heures | H19: En heures et minutes | I19: Aucune des réponses précédentes
A20: 3. SF-PF-CF correspondent :|À la résistance au feu des éléments de construction|À la réaction au feu des matériaux de construction|Aux niveaux d’accès du S.S.I|Aux classements d’E.R.P|Aucune des réponses précédentes | B20: =FIND(". ",A20) -> 2 | C20: =RIGHT(A20, LEN(A20)-(B20+1)) -> SF-PF-CF correspondent :|À la résistance au feu des éléments de construction|À la réaction au feu des matériaux de construction|Aux niveaux d’accès du S.S.I|Aux classements d’E.R.P|Aucune des réponses précédentes | D20: {=_xlfn.TEXTSPLIT(C20,"|")} -> SF-PF-CF correspondent : | E20: À la résistance au feu des éléments de construction | F20: À la réaction au feu des matériaux de construction | G20: Aux niveaux d’accès du S.S.I | H20: Aux classements d’E.R.P | I20: Aucune des réponses précédentes
A21: 4. La réaction au feu d’un matériau peut être notée :|SF|A1|CF|M0|M2|Aucune des réponses précédentes | B21: =FIND(". ",A21) -> 2 | C21: =RIGHT(A21, LEN(A21)-(B21+1)) -> La réaction au feu d’un matériau peut être notée :|SF|A1|CF|M0|M2|Aucune des réponses précédentes | D21: {=_xlfn.TEXTSPLIT(C21,"|")} -> La réaction au feu d’un matériau peut être notée : | E21: SF | F21: A1 | G21: CF | H21: M0 | I21: M2 | J21: Aucune des réponses précédentes
A22: 5. Le classement M1 correspond à :|La résistance au feu d’une porte|Le potentiel d’extinction d’un extincteur|La réaction au feu d’un matériau|La manœuvre mensuelle obligatoire|Aucune des réponses précédentes | B22: =FIND(". ",A22) -> 2 | C22: =RIGHT(A22, LEN(A22)-(B22+1)) -> Le classement M1 correspond à :|La résistance au feu d’une porte|Le potentiel d’extinction d’un extincteur|La réaction au feu d’un matériau|La manœuvre mensuelle obligatoire|Aucune des réponses précédentes | D22: {=_xlfn.TEXTSPLIT(C22,"|")} -> Le classement M1 correspond à : | E22: La résistance au feu d’une porte | F22: Le potentiel d’extinction d’un extincteur | G22: La réaction au feu d’un matériau | H22: La manœuvre mensuelle obligatoire | I22: Aucune des réponses précédentes
A23: 6. Un classement de réaction au feu est demandé pour :|Un revêtement mural|Un rétroprojecteur|Un revêtement de sol|Un gros mobilier|Aucune des réponses précédentes | B23: =FIND(". ",A23) -> 2 | C23: =RIGHT(A23, LEN(A23)-(B23+1)) -> Un classement de réaction au feu est demandé pour :|Un revêtement mural|Un rétroprojecteur|Un revêtement de sol|Un gros mobilier|Aucune des réponses précédentes | D23: {=_xlfn.TEXTSPLIT(C23,"|")} -> Un classement de réaction au feu est demandé pour : | E23: Un revêtement mural | F23: Un rétroprojecteur | G23: Un revêtement de sol | H23: Un gros mobilier | I23: Aucune des réponses précédentes
A24: 7. En ERP, donnez les principales règles pour le revêtement des escaliers encloisonnés ?|M1 pour les murs|M2 pour le sol|M3 pour le plafond|M4 pour le sol|M1 pour le plafond|M3 pour le sol|Aucune des réponses précédentes | B24: =FIND(". ",A24) -> 2 | C24: =RIGHT(A24, LEN(A24)-(B24+1)) -> En ERP, donnez les principales règles pour le revêtement des escaliers encloisonnés ?|M1 pour les murs|M2 pour le sol|M3 pour le plafond|M4 pour le sol|M1 pour le plafond|M3 pour le sol|Aucune des réponses précédentes | D24: {=_xlfn.TEXTSPLIT(C24,"|")} -> En ERP, donnez les principales règles pour le revêtement des escaliers encloisonnés ? | E24: M1 pour les murs | F24: M2 pour le sol | G24: M3 pour le plafond | H24: M4 pour le sol | I24: M1 pour le plafond | J24: M3 pour le sol | K24: Aucune des réponses précédentes
A25: 8. La résistance au feu s’applique :|Aux meubles|Aux sapins de Noël|Aux objets|Aux éléments de construction|Aucune des réponses précédentes | B25: =FIND(". ",A25) -> 2 | C25: =RIGHT(A25, LEN(A25)-(B25+1)) -> La résistance au feu s’applique :|Aux meubles|Aux sapins de Noël|Aux objets|Aux éléments de construction|Aucune des réponses précédentes | D25: {=_xlfn.TEXTSPLIT(C25,"|")} -> La résistance au feu s’applique : | E25: Aux meubles | F25: Aux sapins de Noël | G25: Aux objets | H25: Aux éléments de construction | I25: Aucune des réponses précédentes
A26: 9. Un élément de construction qui résiste au feu peut être classé :|Coupe-feu|REI|Pare-feu|A.E.S.|Stable au feu|Aucune des réponses précédentes | B26: =FIND(". ",A26) -> 2 | C26: =RIGHT(A26, LEN(A26)-(B26+1)) -> Un élément de construction qui résiste au feu peut être classé :|Coupe-feu|REI|Pare-feu|A.E.S.|Stable au feu|Aucune des réponses précédentes | D26: {=_xlfn.TEXTSPLIT(C26,"|")} -> Un élément de construction qui résiste au feu peut être classé : | E26: Coupe-feu | F26: REI | G26: Pare-feu | H26: A.E.S. | I26: Stable au feu | J26: Aucune des réponses précédentes
A27: [2] Classement des ERP (1) | B27: =FIND(". ",A27) -> #VALUE! | C27: =RIGHT(A27, LEN(A27)-(B27+1)) -> #VALUE! | D27: {=_xlfn.TEXTSPLIT(C27,"|")} -> #VALUE!
A28: [2.1] ERP | B28: =FIND(". ",A28) -> #VALUE! | C28: =RIGHT(A28, LEN(A28)-(B28+1)) -> #VALUE! | D28: {=_xlfn.TEXTSPLIT(C28,"|")} -> #VALUE!
A29: 1. Quel établissement suivant est classé en type OA ?|Un hôtel habité|Un hôtel d’altitude|Une habitation occupée|Un organisme agréé|Aucune des réponses précédentes | B29: =FIND(". ",A29) -> 2 | C29: =RIGHT(A29, LEN(A29)-(B29+1)) -> Quel établissement suivant est classé en type OA ?|Un hôtel habité|Un hôtel d’altitude|Une habitation occupée|Un organisme agréé|Aucune des réponses précédentes | D29: {=_xlfn.TEXTSPLIT(C29,"|")} -> Quel établissement suivant est classé en type OA ? | E29: Un hôtel habité | F29: Un hôtel d’altitude | G29: Une habitation occupée | H29: Un organisme agréé | I29: Aucune des réponses précédentes
A30: 2. Qu’est-ce qu’un établissement de type PA ?|Un parc automobile|Un stand de tir|Un centre de formation professionnel pour adultes|Aucune des réponses précédentes | B30: =FIND(". ",A30) -> 2 | C30: =RIGHT(A30, LEN(A30)-(B30+1)) -> Qu’est-ce qu’un établissement de type PA ?|Un parc automobile|Un stand de tir|Un centre de formation professionnel pour adultes|Aucune des réponses précédentes | D30: {=_xlfn.TEXTSPLIT(C30,"|")} -> Qu’est-ce qu’un établissement de type PA ? | E30: Un parc automobile | F30: Un stand de tir | G30: Un centre de formation professionnel pour adultes | H30: Aucune des réponses précédentes
A31: 3. Parmi les établissements suivants, lesquels sont des ERP ?|Un train de voyageur|Un parc d’exposition|Une salle de concert|Un dépôt de gaz|Une menuiserie|Aucune des réponses précédentes | B31: =FIND(". ",A31) -> 2 | C31: =RIGHT(A31, LEN(A31)-(B31+1)) -> Parmi les établissements suivants, lesquels sont des ERP ?|Un train de voyageur|Un parc d’exposition|Une salle de concert|Un dépôt de gaz|Une menuiserie|Aucune des réponses précédentes | D31: {=_xlfn.TEXTSPLIT(C31,"|")} -> Parmi les établissements suivants, lesquels sont des ERP ? | E31: Un train de voyageur | F31: Un parc d’exposition | G31: Une salle de concert | H31: Un dépôt de gaz | I31: Une menuiserie | J31: Aucune des réponses précédentes
A32: 4. Quel règlement de sécurité incendie est applicable aux E.R.P. du 1er groupe ?|L’arrêté du 08 mai 1968 modifié|L’arrêté du 18 octobre 1977 modifié|L’arrêté du 25 juin 1980 modifié|L’arrêté du 02 mai 2005 modifié|L’arrêté du 23 août 2008 modifié|Aucune des réponses précédentes | B32: =FIND(". ",A32) -> 2 | C32: =RIGHT(A32, LEN(A32)-(B32+1)) -> Quel règlement de sécurité incendie est applicable aux E.R.P. du 1er groupe ?|L’arrêté du 08 mai 1968 modifié|L’arrêté du 18 octobre 1977 modifié|L’arrêté du 25 juin 1980 modifié|L’arrêté du 02 mai 2005 modifié|L’arrêté du 23 août 2008 modifié|Aucune des réponses précédentes | D32: {=_xlfn.TEXTSPLIT(C32,"|")} -> Quel règlement de sécurité incendie est applicable aux E.R.P. du 1er groupe ? | E32: L’arrêté du 08 mai 1968 modifié | F32: L’arrêté du 18 octobre 1977 modifié | G32: L’arrêté du 25 juin 1980 modifié | H32: L’arrêté du 02 mai 2005 modifié | I32: L’arrêté du 23 août 2008 modifié | J32: Aucune des réponses précédentes
A33: 5. Une maison d’accueil pour handicapés pouvant recevoir 308 personnes est classée :|Type J|Type U|Type R|2ème catégorie|3ème catégorie|4ème catégorie|Aucune des réponses précédentes | B33: =FIND(". ",A33) -> 2 | C33: =RIGHT(A33, LEN(A33)-(B33+1)) -> Une maison d’accueil pour handicapés pouvant recevoir 308 personnes est classée :|Type J|Type U|Type R|2ème catégorie|3ème catégorie|4ème catégorie|Aucune des réponses précédentes | D33: {=_xlfn.TEXTSPLIT(C33,"|")} -> Une maison d’accueil pour handicapés pouvant recevoir 308 personnes est classée : | E33: Type J | F33: Type U | G33: Type R | H33: 2ème catégorie | I33: 3ème catégorie | J33: 4ème catégorie | K33: Aucune des réponses précédentes
A34: 6. Les ERP sont classés par catégorie en fonction :|Du nombre maximum de personnes admises|Du nombre d’étages|Du nombre de locaux|Du nombre de sorties|Aucune des réponses précédentes | B34: =FIND(". ",A34) -> 2 | C34: =RIGHT(A34, LEN(A34)-(B34+1)) -> Les ERP sont classés par catégorie en fonction :|Du nombre maximum de personnes admises|Du nombre d’étages|Du nombre de locaux|Du nombre de sorties|Aucune des réponses précédentes | D34: {=_xlfn.TEXTSPLIT(C34,"|")} -> Les ERP sont classés par catégorie en fonction : | E34: Du nombre maximum de personnes admises | F34: Du nombre d’étages | G34: Du nombre de locaux | H34: Du nombre de sorties | I34: Aucune des réponses précédentes
A35: [3] Classement des IGH (1) | B35: =FIND(". ",A35) -> #VALUE! | C35: =RIGHT(A35, LEN(A35)-(B35+1)) -> #VALUE! | D35: {=_xlfn.TEXTSPLIT(C35,"|")} -> #VALUE!
A36: [2.1] IGH | B36: =FIND(". ",A36) -> #VALUE! | C36: =RIGHT(A36, LEN(A36)-(B36+1)) -> #VALUE! | D36: {=_xlfn.TEXTSPLIT(C36,"|")} -> #VALUE!
A37: 1. Les IGH à usage exclusif de bureaux sont classés de la façon suivante :|GHZ|GHR|GHW1|GHW2|Aucune des réponses précédentes | B37: =FIND(". ",A37) -> 2 | C37: =RIGHT(A37, LEN(A37)-(B37+1)) -> Les IGH à usage exclusif de bureaux sont classés de la façon suivante :|GHZ|GHR|GHW1|GHW2|Aucune des réponses précédentes | D37: {=_xlfn.TEXTSPLIT(C37,"|")} -> Les IGH à usage exclusif de bureaux sont classés de la façon suivante : | E37: GHZ | F37: GHR | G37: GHW1 | H37: GHW2 | I37: Aucune des réponses précédentes
A38: 2. Le classement d’un bâtiment en immeuble de grande hauteur est déterminé d’après :|La catégorie de l’établissement|La surface accessible au public|La hauteur du plancher bas du dernier niveau|La commission de sécurité compétente|Aucune des réponses précédentes | B38: =FIND(". ",A38) -> 2 | C38: =RIGHT(A38, LEN(A38)-(B38+1)) -> Le classement d’un bâtiment en immeuble de grande hauteur est déterminé d’après :|La catégorie de l’établissement|La surface accessible au public|La hauteur du plancher bas du dernier niveau|La commission de sécurité compétente|Aucune des réponses précédentes | D38: {=_xlfn.TEXTSPLIT(C38,"|")} -> Le classement d’un bâtiment en immeuble de grande hauteur est déterminé d’après : | E38: La catégorie de l’établissement | F38: La surface accessible au public | G38: La hauteur du plancher bas du dernier niveau | H38: La commission de sécurité compétente | I38: Aucune des réponses précédentes
A39: 3. Qu’est-ce qu’un GH S ?|Un IGH à usage mixte|Un IGH d’enseignement|Un IGH d’habitation|Un IGH d’archives|Aucune des réponses précédentes | B39: =FIND(". ",A39) -> 2 | C39: =RIGHT(A39, LEN(A39)-(B39+1)) -> Qu’est-ce qu’un GH S ?|Un IGH à usage mixte|Un IGH d’enseignement|Un IGH d’habitation|Un IGH d’archives|Aucune des réponses précédentes | D39: {=_xlfn.TEXTSPLIT(C39,"|")} -> Qu’est-ce qu’un GH S ? | E39: Un IGH à usage mixte | F39: Un IGH d’enseignement | G39: Un IGH d’habitation | H39: Un IGH d’archives | I39: Aucune des réponses précédentes
A40: 4. Est considéré comme IGH, tout bâtiment dont le plancher bas du dernier niveau est situé à plus de :|50 mètres pour les immeubles à usage d’habitation|28 mètres pour les immeubles ne relevant pas de l’habitation|28 mètres pour les immeubles à usage d’habitation|Aucune des réponses précédentes | B40: =FIND(". ",A40) -> 2 | C40: =RIGHT(A40, LEN(A40)-(B40+1)) -> Est considéré comme IGH, tout bâtiment dont le plancher bas du dernier niveau est situé à plus de :|50 mètres pour les immeubles à usage d’habitation|28 mètres pour les immeubles ne relevant pas de l’habitation|28 mètres pour les immeubles à usage d’habitation|Aucune des réponses précédentes | D40: {=_xlfn.TEXTSPLIT(C40,"|")} -> Est considéré comme IGH, tout bâtiment dont le plancher bas du dernier niveau est situé à plus de : | E40: 50 mètres pour les immeubles à usage d’habitation | F40: 28 mètres pour les immeubles ne relevant pas de l’habitation | G40: 28 mètres pour les immeubles à usage d’habitation | H40: Aucune des réponses précédentes
...
